<?xml version="1.0"?>
<robot xmlns:xacro="http://www.ros.org/wiki/xacro" >
  <link name="back_right_wrist">
    <inertial>
      <origin xyz="-0.001195 -0.0001949 -0.02221" rpy="0 0 0" />
      <mass value="0.4" />
      <inertia  ixx="0.0002577449173061704" ixy="0" ixz="0" iyy="0.0002748211730214112" iyz="0" izz="0.00017732372754777532" />
    </inertial>
    <visual>
      <origin
        xyz="0 0 0"
        rpy="0 0 0" />
      <geometry>
        <mesh
          filename="package://clifford_gazebo/meshes/back_right_wrist.STL" />
      </geometry>
      <material
        name="">
        <color
          rgba="0.75294 0.75294 0.75294 1" />
      </material>
    </visual>
    <collision>
      <origin
        xyz="0 0 0"
        rpy="0 0 0" />
      <geometry>
        <mesh
          filename="package://clifford_gazebo/meshes/back_right_wrist.STL" />
      </geometry>
    </collision>
  </link>

  <joint name="back_right_wrist_joint" type="revolute">
    <origin
      xyz="-0.095875 -0.070109 0.00015658"
      rpy="0 0 0" />
    <parent
      link="base_footprint" />
    <child
      link="back_right_wrist" />
    <axis
      xyz="-1 0 0" />
    <limit
      lower="-2.618"
      upper="2.618"
      effort="1.5"
      velocity="10.5" />
    <dynamics damping="0.9" friction="0.9" />
  </joint>

  <link name="back_right_leg">
    <inertial>
      <origin xyz="0.020216 0.00051528 -0.049773" rpy="0 0 0" />
      <mass value="0.5" />
      <inertia  ixx="0.0006608284339635455" ixy="0" ixz="0" iyy="0.0008622624687228709" iyz="0" izz="0.0003780096169014544" />
    </inertial>
    <visual>
      <origin
        xyz="0 0 0"
        rpy="0 0 0" />
      <geometry>
        <mesh
          filename="package://clifford_gazebo/meshes/back_right_leg.STL" />
      </geometry>
      <material
        name="">
        <color
          rgba="0.75294 0.75294 0.75294 1" />
      </material>
    </visual>
    <collision>
      <origin
        xyz="0 0 0"
        rpy="0 0 0" />
      <geometry>
        <mesh
          filename="package://clifford_gazebo/meshes/back_right_leg.STL" />
      </geometry>
    </collision>
  </link>

  <joint name="back_right_leg_joint" type="revolute">
    <origin
      xyz="-2.4999E-05 -1.4092E-05 -0.048"
      rpy="0 1.5708 0" />
    <parent
      link="back_right_wrist" />
    <child
      link="back_right_leg" />
    <axis
      xyz="0.00081441 1 0" />
    <limit
      lower="-2.618"
      upper="2.618"
      effort="1.5"
      velocity="10.5" />
    <dynamics damping="0.9" friction="0.9" />
  </joint>

  <link name="back_right_foot">
    <inertial>
      <origin xyz="-0.0061315 -0.0056259 -0.049828" rpy="0 0 0" />
      <mass value="0.4" />
      <inertia  ixx="0.0008779782398059858" ixy="0" ixz="0" iyy="0.0008219879283309588" iyz="0" izz="0.00010420587850584241" />
    </inertial>
    <visual>
      <origin
        xyz="0 0 0"
        rpy="0 0 0" />
      <geometry>
        <mesh
          filename="package://clifford_gazebo/meshes/back_right_foot.STL" />
      </geometry>
      <material
        name="">
        <color
          rgba="0.75294 0.75294 0.75294 1" />
      </material>
    </visual>
    <collision>
      <origin
        xyz="0 0 0"
        rpy="0 0 0" />
      <geometry>
        <mesh
          filename="package://clifford_gazebo/meshes/back_right_foot.STL" />
      </geometry>
    </collision>
  </link>
  
  <joint name="back_right_foot_joint" type="revolute">
    <origin
      xyz="0.055242 -4.4986E-05 -0.090507"
      rpy="3.1416 0 3.1416" />
    <parent
      link="back_right_leg" />
    <child
      link="back_right_foot" />
    <axis
      xyz="-0.00081441 1 0" />
    <limit
      lower="-2.618"
      upper="2.618"
      effort="1.5"
      velocity="10.5" />
    <dynamics damping="0.9" friction="0.9" />
  </joint>
</robot>