<?xml version="1.0"?>
<robot xmlns:xacro="http://www.ros.org/wiki/xacro" >
  <link name="back_left_wrist">
    <inertial>
      <origin xyz="0.001195 0.00015872 -0.022211" rpy="0 0 0" />
      <mass value="0.4" />
      <inertia  ixx="0.0002575811927139552" ixy="0" ixz="0" iyy="0.00027465080011192705" iyz="0" izz="0.00017733037586504426" />
    </inertial>
    <visual>
      <origin
        xyz="0 0 0"
        rpy="0 0 0" />
      <geometry>
        <mesh
          filename="package://clifford_gazebo/meshes/back_left_wrist.STL" />
      </geometry>
      <material
        name="">
        <color
          rgba="0.75294 0.75294 0.75294 1" />
      </material>
    </visual>
    <collision>
      <origin
        xyz="0 0 0"
        rpy="0 0 0" />
      <geometry>
        <mesh
          filename="package://clifford_gazebo/meshes/back_left_wrist.STL" />
      </geometry>
    </collision>
  </link>

  <joint name="back_left_wrist_joint" type="revolute">
    <origin
      xyz="-0.095875 0.070091 0.00015658"
      rpy="0 0 0" />
    <parent
      link="base_footprint" />
    <child
      link="back_left_wrist" />
    <axis
      xyz="1 0 0" />
    <limit
      lower="-2.618"
      upper="2.618"
      effort="1.5"
      velocity="10.5" />
    <dynamics damping="0.9" friction="0.9" />
  </joint>

  <link
    name="back_left_leg">
    <inertial>
      <origin
        xyz="0.02029 0.00051522 -0.049743"
        rpy="0 0 0" />
      <mass value="0.5" />
      <inertia  ixx="0.0006601698078507005" ixy="0" ixz="0" iyy="0.0008625781128657934" iyz="0" izz="0.0003789841729590441" />
    </inertial>
    <visual>
      <origin
        xyz="0 0 0"
        rpy="0 0 0" />
      <geometry>
        <mesh
          filename="package://clifford_gazebo/meshes/back_left_leg.STL" />
      </geometry>
      <material
        name="">
        <color
          rgba="0.75294 0.75294 0.75294 1" />
      </material>
    </visual>
    <collision>
      <origin
        xyz="0 0 0"
        rpy="0 0 0" />
      <geometry>
        <mesh
          filename="package://clifford_gazebo/meshes/back_left_leg.STL" />
      </geometry>
    </collision>
  </link>

  <joint name="back_left_leg_joint" type="revolute">
    <origin
      xyz="2.4999E-05 -6.4091E-05 -0.048"
      rpy="0 1.5708 0" />
    <parent
      link="back_left_wrist" />
    <child
      link="back_left_leg" />
    <axis
      xyz="0.00081441 1 0" />
    <limit
      lower="-2.618"
      upper="2.618"
      effort="1.5"
      velocity="10.5" />
    <dynamics damping="0.9" friction="0.9" />
  </joint>

  <link name="back_left_foot">
    <inertial>
      <origin xyz="-0.0061406 0.0056159 -0.049828" rpy="0 0 0" />
      <mass value="0.4" />
      <inertia  ixx="0.0008779825495322561" ixy="0" ixz="0" iyy="0.0008219382925804376" iyz="0" izz="0.00010416055248159151" />
    </inertial>
    <visual>
      <origin
        xyz="0 0 0"
        rpy="0 0 0" />
      <geometry>
        <mesh
          filename="package://clifford_gazebo/meshes/back_left_foot.STL" />
      </geometry>
      <material
        name="">
        <color
          rgba="0.75294 0.75294 0.75294 1" />
      </material>
    </visual>
    <collision>
      <origin
        xyz="0 0 0"
        rpy="0 0 0" />
      <geometry>
        <mesh
          filename="package://clifford_gazebo/meshes/back_left_foot.STL" />
      </geometry>
    </collision>
  </link>
  
  <joint name="back_left_foot_joint" type="revolute">
    <origin
      xyz="0.055376 -4.5095E-05 -0.090425"
      rpy="3.1416 0 3.1416" />
    <parent
      link="back_left_leg" />
    <child
      link="back_left_foot" />
    <axis
      xyz="-0.00081441 1 0" />
    <limit
      lower="-2.618"
      upper="2.618"
      effort="1.5"
      velocity="10.5" />
    <dynamics damping="0.9" friction="0.9" />
  </joint>
</robot>