<?xml version="1.0"?>
<robot xmlns:xacro="http://www.ros.org/wiki/xacro" >
  <!-- Description fo Clifford's back right shoulder -->
  <link name="back_right_shoulder">
    <inertial>
      <origin xyz="-0.00119495363353912 -0.000176809986865901 -0.0222104021426802" rpy="0 0 0" />
      <mass value="0.0251261421169069" />
      <inertia
        ixx="7.27601970126056E-06"
        ixy="-2.80375542182697E-12"
        ixz="4.263737475911E-07"
        iyy="7.42765684115746E-06"
        iyz="1.05248374132493E-08"
        izz="9.65290321850445E-06" />
    </inertial>
    <visual>
      <origin xyz="0 0 0" rpy="0 0 0" />
      <geometry>
        <mesh filename="package://clifford_description/meshes/back_right_shoulder.STL" />
      </geometry>
      <material name="">
        <color rgba="0.752941176470588 0.752941176470588 0.752941176470588 1" />
      </material>
    </visual>
    <collision>
      <origin xyz="0 0 0" rpy="0 0 0" />
      <geometry>
        <mesh filename="package://clifford_description/meshes/back_right_shoulder.STL" />
      </geometry>
    </collision>
  </link>

  <joint name="back_right_shoulder_joint" type="revolute">
    <origin xyz="-0.095875 -0.070109 0.00015658" rpy="0 0 0" />
    <parent link="base_footprint" />
    <child link="back_right_shoulder" />
    <axis xyz="-1 0 0" />
    <limit lower="-2.618" upper="2.618" effort="1.5" velocity="10.5" />
    <dynamics damping="0.4" friction="0.4" />
  </joint>

  <!-- Description fo Clifford's back right elbow -->
  <link name="back_right_elbow">
    <inertial>
      <origin xyz="0.0530168092815066 0.000531743532156383 -0.00867531583230777" rpy="0 0 0" />
      <mass value="0.128871239808788" />
      <inertia
        ixx="1.82866748457515E-05"
        ixy="9.03752705072398E-07"
        ixz="-1.81783232455234E-09"
        iyy="3.16365309194226E-05"
        iyz="1.06647082290352E-07"
        izz="3.20527619287412E-05" />
    </inertial>
    <visual>
      <origin xyz="0 0 0" rpy="0 0 0" />
      <geometry>
        <mesh filename="package://clifford_description/meshes/back_right_elbow.STL" />
      </geometry>
      <material name="">
        <color rgba="0.752941176470588 0.752941176470588 0.752941176470588 1" />
      </material>
    </visual>
    <collision>
      <origin xyz="0 0 0" rpy="0 0 0" />
      <geometry>
        <mesh filename="package://clifford_description/meshes/back_right_elbow.STL" />
      </geometry>
    </collision>
  </link>

  <joint name="back_right_elbow_joint" type="revolute">
    <origin xyz="-2.4999E-05 2.4999E-05 -0.048" rpy="0 1.5708 0" />
    <parent link="back_right_shoulder" />
    <child link="back_right_elbow" />
    <axis xyz="0 1 0" />
    <limit lower="-2.618" upper="2.618" effort="1.5" velocity="10.5" />
    <dynamics damping="0.4" friction="0.4" />
  </joint>

  <!-- Description fo Clifford's back right wrist -->
  <link name="back_right_wrist">
    <inertial>
      <origin xyz="-0.0501854871379641 -0.00562091408227047 -0.00139057258160866" rpy="0 0 0" />
      <mass value="0.0434019946211029" />
      <inertia
        ixx="9.31273863324073E-06"
        ixy="-5.08252101518028E-06"
        ixz="-3.79907304251183E-06"
        iyy="4.22798179487165E-05"
        iyz="-3.54794316085271E-07"
        izz="4.88117060695608E-05" />
    </inertial>
    <visual>
      <origin xyz="0 0 0" rpy="0 0 0" />
      <geometry>
        <mesh filename="package://clifford_description/meshes/back_right_wrist.STL" />
      </geometry>
      <material name="">
        <color rgba="0.752941176470588 0.752941176470588 0.752941176470588 1" />
      </material>
    </visual>
    <collision>
      <origin xyz="0 0 0" rpy="0 0 0" />
      <geometry>
        <mesh filename="package://clifford_description/meshes/back_right_wrist.STL" />
      </geometry>
    </collision>
  </link>

  <joint name="back_right_wrist_joint" type="revolute">
    <origin xyz="0.106033686469265 0 0" rpy="3.14159265358979 0 3.14159265358979" />
    <parent link="back_right_elbow" />
    <child link="back_right_wrist" />
    <axis xyz="1.32856310796055E-05 0.999999999911745 0" />
    <limit lower="-2.618" upper="2.618" effort="1.5" velocity="10.5" />
    <dynamics damping="0.4" friction="0.4" />
  </joint>

  <!-- Description fo Clifford's back right foott -->
  <link name="back_right_foot" />
  
  <joint name="back_right_foot_joint" type="fixed">
    <origin xyz="-0.141702532861941 -0.0132250006870532 -0.014113048791347" rpy="0 0 0" />
    <parent link="back_right_wrist" />
    <child link="back_right_foot" />
    <axis xyz="0 0 0" />
  </joint>
</robot>